Workbook
Name comp_prices_tbl: Table1[]
Name Comp_tbl: Table1[]
Name Master_tbl: Table5[]
Name Slicer_category: #N/A
Name Slicer_sale_date: #N/A

Sheet Sheet1
A1: sale_id | B1: product_id | C1: sale_date | D1: quantity_sold | E1: discount_percent | F1: final_sale_price | G1: product_name | H1: category | I1: cost_price | J1: base_price | K1: rating | L1: competitor_price | M1: avg_comp_price | N1: Revenue | O1: Profit | P1: Price Difference | Q1: Price Difference %
A2: 998 | B2: 34 | C2: 45615 | D2: 35 | E2: 7 | F2: 1212.1527 | G2: Doll 34 | H2: Toys | I2: 782.034 | J2: 1303.39 | K2: 2 | L2: 1355.9981 | M2: 4145.444 | N2: 42425.345 | O2: 15054.155 | P2: -2933.2913 | Q2: -0.707594
A3: 984 | B3: 89 | C3: 45298 | D3: 49 | E3: 8 | F3: 927.7004 | G3: Remote Car 89 | H3: Toys | I3: 605.022 | J3: 1008.37 | K3: 4 | L3: 1103.1128 | M3: 913.02 | N3: 45457.32 | O3: 15811.242 | P3: 14.6804 | Q3: 0.016078947
A4: 3 | B4: 27 | C4: 45339 | D4: 14 | E4: 2 | F4: 1590.442 | G4: Action Figure 27 | H4: Toys | I4: 973.74 | J4: 1622.9 | K4: 1 | L4: 1917.2436 | M4: 4440.4167 | N4: 22266.188 | O4: 8633.828 | P4: -2849.9747 | Q4: -0.64182595
A5: 983 | B5: 98 | C5: 45624 | D5: 48 | E5: 3 | F5: 7573.4496 | G5: Puzzle Set 98 | H5: Toys | I5: 4684.608 | J5: 7807.68 | K5: 3 | L5: 8468.6419 | M5: 6533.69 | N5: 363525.58 | O5: 138664.4 | P5: 1039.7596 | Q5: 0.15913819
A6: 976 | B6: 34 | C6: 45708 | D6: 41 | E6: 7 | F6: 1212.1527 | G6: Doll 34 | H6: Toys | I6: 782.034 | J6: 1303.39 | K6: 2 | L6: 1465.5121 | M6: 4145.444 | N6: 49698.261 | O6: 17634.867 | P6: -2933.2913 | Q6: -0.707594
A7: 974 | B7: 150 | C7: 45875 | D7: 28 | E7: 7 | F7: 2129.4396 | G7: Puzzle Set 150 | H7: Toys | I7: 1373.832 | J7: 2289.72 | K7: 3 | L7: 2572.7553 | M7: 1810.3167 | N7: 59624.309 | O7: 21157.013 | P7: 319.12293 | Q7: 0.17628017
A8: 973 | B8: 11 | C8: 45586 | D8: 21 | E8: 2 | F8: 3136.196 | G8: Remote Car 11 | H8: Toys | I8: 1920.12 | J8: 3200.2 | K8: 1 | L8: 3575.579 | M8: 7089.33 | N8: 65860.116 | O8: 25537.596 | P8: -3953.134 | Q8: -0.55761743
A9: 972 | B9: 102 | C9: 45271 | D9: 25 | E9: 7 | F9: 3853.8642 | G9: Action Figure 102 | H9: Toys | I9: 2486.364 | J9: 4143.94 | K9: 4 | L9: 4842.533 | M9: 2740.84 | N9: 96346.605 | O9: 34187.505 | P9: 1113.0242 | Q9: 0.40608872
A10: 968 | B10: 89 | C10: 45907 | D10: 39 | E10: 10 | F10: 907.533 | G10: Remote Car 89 | H10: Toys | I10: 605.022 | J10: 1008.37 | K10: 4 | L10: 1197.3654 | M10: 913.02 | N10: 35393.787 | O10: 11797.929 | P10: -5.487 | Q10: -0.006009726
A11: 963 | B11: 106 | C11: 45197 | D11: 22 | E11: 10 | F11: 1290.627 | G11: Doll 106 | H11: Toys | I11: 860.418 | J11: 1434.03 | K11: 2 | L11: 1438.5138 | M11: 695.384 | N11: 28393.794 | O11: 9464.598 | P11: 595.243 | Q11: 0.8559918
A12: 960 | B12: 105 | C12: 45655 | D12: 16 | E12: 3 | F12: 4018.7876 | G12: Action Figure 105 | H12: Toys | I12: 2485.848 | J12: 4143.08 | K12: 3 | L12: 4549.7417 | M12: 4778.885 | N12: 64300.602 | O12: 24527.034 | P12: -760.0974 | Q12: -0.15905329
A13: 12 | B13: 50 | C13: 45784 | D13: 47 | E13: 9 | F13: 1234.597 | G13: Doll 50 | H13: Toys | I13: 814.02 | J13: 1356.7 | K13: 3 | L13: 1594.9775 | M13: 4909.6483 | N13: 58026.059 | O13: 19767.119 | P13: -3675.0513 | Q13: -0.74853657
... A162: 174 | B162: 69 | C162: 45970 | D162: 38 | E162: 4 | F162: 7160.352 | G162: Doll 69 | H162: Toys | I162: 4475.22 | J162: 7458.7 | K162: 3 | L162: 8908.4238 | M162: 809.576 | N162: 272093.38 | O162: 102035.02 | P162: 6350.776 | Q162: 7.8445705

Sheet Sheet2
A1: sale_id | B1: product_id | C1: sale_date | D1: quantity_sold | E1: discount_percent | F1: final_sale_price | G1: product_name | H1: category | I1: cost_price | J1: base_price | K1: rating | L1: competitor_price | M1: avg_comp_price | N1: Revenue | O1: Profit | P1: Price Difference | Q1: Price Difference %
A2: 982 | B2: 61 | C2: 45078 | D2: 41 | E2: 9 | F2: 2222.4384 | G2: Green Tea 61 | H2: Grocery | I2: 1465.344 | J2: 2442.24 | K2: 5 | L2: 2491.9872 | M2: 411.756 | N2: 91119.974 | O2: 31040.87 | P2: 1810.6824 | Q2: 4.3974645
A3: 980 | B3: 1 | C3: 45258 | D3: 16 | E3: 3 | F3: 1853.6215 | G3: Wheat Flour 1 | H3: Grocery | I3: 1146.57 | J3: 1910.95 | K3: 1 | L3: 2243.4942 | M3: 4785.0083 | N3: 29657.944 | O3: 11312.824 | P3: -2931.3868 | Q3: -0.61261896
A4: 975 | B4: 1 | C4: 45460 | D4: 20 | E4: 4 | F4: 1834.512 | G4: Wheat Flour 1 | H4: Grocery | I4: 1146.57 | J4: 1910.95 | K4: 1 | L4: 2061.9136 | M4: 4785.0083 | N4: 36690.24 | O4: 13758.84 | P4: -2950.4963 | Q4: -0.61661258
A5: 954 | B5: 113 | C5: 45737 | D5: 10 | E5: 5 | F5: 4587.702 | G5: Green Tea 113 | H5: Grocery | I5: 2897.496 | J5: 4829.16 | K5: 1 | L5: 5774.448 | M5: 4302.05 | N5: 45877.02 | O5: 16902.06 | P5: 285.652 | Q5: 0.066399042
A6: 930 | B6: 58 | C6: 44948 | D6: 41 | E6: 6 | F6: 1070.2652 | G6: Wheat Flour 58 | H6: Grocery | I6: 683.148 | J6: 1138.58 | K6: 2 | L6: 1345.0391 | M6: 1439.8525 | N6: 43880.873 | O6: 15871.805 | P6: -369.5873 | Q6: -0.25668414
A7: 926 | B7: 62 | C7: 45531 | D7: 6 | E7: 4 | F7: 3319.6224 | G7: Olive Oil 62 | H7: Grocery | I7: 2074.764 | J7: 3457.94 | K7: 4 | L7: 3640.2205 | M7: 5560.3267 | N7: 19917.734 | O7: 7469.1504 | P7: -2240.7043 | Q7: -0.40298069
A8: 923 | B8: 37 | C8: 45742 | D8: 49 | E8: 5 | F8: 3668.3965 | G8: Sugar 37 | H8: Grocery | I8: 2316.882 | J8: 3861.47 | K8: 1 | L8: 4944.6298 | M8: 2618.576 | N8: 179751.43 | O8: 66224.211 | P8: 1049.8205 | Q8: 0.40091275
A9: 916 | B9: 119 | C9: 45275 | D9: 50 | E9: 10 | F9: 1747.719 | G9: Wheat Flour 119 | H9: Grocery | I9: 1165.146 | J9: 1941.91 | K9: 4 | L9: 2205.6526 | M9: 4902.354 | N9: 87385.95 | O9: 29128.65 | P9: -3154.635 | Q9: -0.64349392
A10: 910 | B10: 41 | C10: 45027 | D10: 6 | E10: 5 | F10: 2927.3965 | G10: Olive Oil 41 | H10: Grocery | I10: 1848.882 | J10: 3081.47 | K10: 1 | L10: 3224.1138 | M10: 1589.125 | N10: 17564.379 | O10: 6471.087 | P10: 1338.2715 | Q10: 0.84214363
A11: 907 | B11: 61 | C11: 45786 | D11: 2 | E11: 7 | F11: 2271.2832 | G11: Green Tea 61 | H11: Grocery | I11: 1465.344 | J11: 2442.24 | K11: 5 | L11: 2777.3915 | M11: 411.756 | N11: 4542.5664 | O11: 1611.8784 | P11: 1859.5272 | Q11: 4.5160901
A12: 905 | B12: 119 | C12: 45325 | D12: 26 | E12: 3 | F12: 1883.6527 | G12: Wheat Flour 119 | H12: Grocery | I12: 1165.146 | J12: 1941.91 | K12: 4 | L12: 2491.0344 | M12: 4902.354 | N12: 48974.97 | O12: 18681.174 | P12: -3018.7013 | Q12: -0.61576567
A13: 901 | B13: 24 | C13: 45760 | D13: 35 | E13: 6 | F13: 3756.7288 | G13: Rice Pack 24 | H13: Grocery | I13: 2397.912 | J13: 3996.52 | K13: 4 | L13: 5142.8719 | M13: 3028.7733 | N13: 131485.51 | O13: 47558.588 | P13: 727.95547 | Q13: 0.24034663
... A121: 120 | B121: 66 | C121: 45555 | D121: 6 | E121: 8 | F121: 5359.0092 | G121: Olive Oil 66 | H121: Grocery | I121: 3495.006 | J121: 5825.01 | K121: 1 | L121: 6734.6258 | M121: 6051.738 | N121: 32154.055 | O121: 11184.019 | P121: -692.7288 | Q121: -0.11446774

Sheet Sheet3
A1: sale_id | B1: product_id | C1: sale_date | D1: quantity_sold | E1: discount_percent | F1: final_sale_price | G1: product_name | H1: category | I1: cost_price | J1: base_price | K1: rating | L1: competitor_price | M1: avg_comp_price | N1: Revenue | O1: Profit | P1: Price Difference | Q1: Price Difference %
A2: 944 | B2: 108 | C2: 44947 | D2: 41 | E2: 4 | F2: 806.9184 | G2: Lipstick 108 | H2: Beauty | I2: 504.324 | J2: 840.54 | K2: 3 | L2: 989.3084 | M2: 5163.712 | N2: 33083.654 | O2: 12406.37 | P2: -4356.7936 | Q2: -0.84373288
A3: 939 | B3: 39 | C3: 44942 | D3: 22 | E3: 8 | F3: 2950.9736 | G3: Perfume 39 | H3: Beauty | I3: 1924.548 | J3: 3207.58 | K3: 1 | L3: 3636.3627 | M3: 9555.608 | N3: 64921.419 | O3: 22581.363 | P3: -6604.6344 | Q3: -0.69117888
A4: 932 | B4: 16 | C4: 44957 | D4: 39 | E4: 9 | F4: 6144.138 | G4: Cookbook 16 | H4: Books | I4: 4051.08 | J4: 6751.8 | K4: 4 | L4: 8036.4471 | M4: 6827.794 | N4: 239621.38 | O4: 81629.262 | P4: -683.656 | Q4: -0.10012839
A5: 930 | B5: 58 | C5: 44948 | D5: 41 | E5: 6 | F5: 1070.2652 | G5: Wheat Flour 58 | H5: Grocery | I5: 683.148 | J5: 1138.58 | K5: 2 | L5: 1345.0391 | M5: 1439.8525 | N5: 43880.873 | O5: 15871.805 | P5: -369.5873 | Q5: -0.25668414
A6: 894 | B6: 127 | C6: 44951 | D6: 46 | E6: 5 | F6: 5216.032 | G6: Gym Gloves 127 | H6: Sports | I6: 3294.336 | J6: 5490.56 | K6: 1 | L6: 5971.1069 | M6: 5984.3333 | N6: 239937.47 | O6: 88398.016 | P6: -768.30133 | Q6: -0.12838545
A7: 821 | B7: 118 | C7: 44935 | D7: 29 | E7: 5 | F7: 2991.7875 | G7: Doll 118 | H7: Toys | I7: 1889.55 | J7: 3149.25 | K7: 5 | L7: 3395.4995 | M7: 224.524 | N7: 86761.837 | O7: 31964.887 | P7: 2767.2635 | Q7: 12.325023
A8: 799 | B8: 123 | C8: 44940 | D8: 50 | E8: 10 | F8: 4164.858 | G8: Sunglasses 123 | H8: Fashion | I8: 2776.572 | J8: 4627.62 | K8: 2 | L8: 5468.9961 | M8: 809.948 | N8: 208242.9 | O8: 69414.3 | P8: 3354.91 | Q8: 4.1421301
A9: 793 | B9: 65 | C9: 44931 | D9: 41 | E9: 4 | F9: 4330.9056 | G9: Biography 65 | H9: Books | I9: 2706.816 | J9: 4511.36 | K9: 1 | L9: 4577.5286 | M9: 1786.8475 | N9: 177567.13 | O9: 66587.674 | P9: 2544.0581 | Q9: 1.423769
A10: 782 | B10: 16 | C10: 44944 | D10: 19 | E10: 8 | F10: 6211.656 | G10: Cookbook 16 | H10: Books | I10: 4051.08 | J10: 6751.8 | K10: 4 | L10: 8363.2202 | M10: 6827.794 | N10: 118021.46 | O10: 41050.944 | P10: -616.138 | Q10: -0.090239688
A11: 765 | B11: 22 | C11: 44954 | D11: 3 | E11: 5 | F11: 1552.775 | G11: Dress 22 | H11: Fashion | I11: 980.7 | J11: 1634.5 | K11: 1 | L11: 1756.6336 | M11: 3187.445 | N11: 4658.325 | O11: 1716.225 | P11: -1634.67 | Q11: -0.5128465
A12: 744 | B12: 78 | C12: 44948 | D12: 34 | E12: 10 | F12: 779.166 | G12: Biography 78 | H12: Books | I12: 519.444 | J12: 865.74 | K12: 4 | L12: 1110.1157 | M12: 398.392 | N12: 26491.644 | O12: 8830.548 | P12: 380.774 | Q12: 0.95577722
A13: 742 | B13: 18 | C13: 44936 | D13: 17 | E13: 9 | F13: 7676.7145 | G13: Coffee Beans 18 | H13: Grocery | I13: 5061.57 | J13: 8435.95 | K13: 3 | L13: 10325.956 | M13: 1552.924 | N13: 130504.15 | O13: 44457.457 | P13: 6123.7905 | Q13: 3.9433936
... A34: 57 | B34: 119 | C34: 44934 | D34: 27 | E34: 7 | F34: 1805.9763 | G34: Wheat Flour 119 | H34: Grocery | I34: 1165.146 | J34: 1941.91 | K34: 4 | L34: 2278.025 | M34: 4902.354 | N34: 48761.36 | O34: 17302.418 | P34: -3096.3777 | Q34: -0.63161039

Sheet Sheet4
A1: sale_id | B1: product_id | C1: sale_date | D1: quantity_sold | E1: discount_percent | F1: final_sale_price | G1: product_name | H1: category | I1: cost_price | J1: base_price | K1: rating | L1: competitor_price | M1: avg_comp_price | N1: Revenue | O1: Profit | P1: Price Difference | Q1: Price Difference % | R1: Profit_margin
A2: 996 | B2: 88 | C2: 45680 | D2: 4 | E2: 5 | F2: 5924.5135 | G2: Tablet 88 | H2: Electronics | I2: 3741.798 | J2: 6236.33 | K2: 5 | L2: 7706.0076 | M2: 4981.505 | N2: 23698.054 | O2: 8730.862 | P2: 943.0085 | Q2: 0.18930193 | R2: 0.36842105
A3: 992 | B3: 28 | C3: 45856 | D3: 35 | E3: 6 | F3: 5373.6228 | G3: Water Purifier 28 | H3: Home Appliances | I3: 3429.972 | J3: 5716.62 | K3: 5 | L3: 6945.0728 | M3: 3542.956 | N3: 188076.8 | O3: 68027.778 | P3: 1830.6668 | Q3: 0.51670605 | R3: 0.36170213
A4: 991 | B4: 135 | C4: 45723 | D4: 6 | E4: 4 | F4: 7468.5216 | G4: Water Purifier 135 | H4: Home Appliances | I4: 4667.826 | J4: 7779.71 | K4: 5 | L4: 9810.9015 | M4: 4172.7833 | N4: 44811.13 | O4: 16804.174 | P4: 3295.7383 | Q4: 0.78981773 | R4: 0.375
A5: 985 | B5: 80 | C5: 45758 | D5: 36 | E5: 6 | F5: 939.1258 | G5: Washing Machine 80 | H5: Home Appliances | I5: 599.442 | J5: 999.07 | K5: 5 | L5: 1235.9662 | M5: 4319.1967 | N5: 33808.529 | O5: 12228.617 | P5: -3380.0709 | Q5: -0.78256934 | R5: 0.36170213
A6: 982 | B6: 61 | C6: 45078 | D6: 41 | E6: 9 | F6: 2222.4384 | G6: Green Tea 61 | H6: Grocery | I6: 1465.344 | J6: 2442.24 | K6: 5 | L6: 2491.9872 | M6: 411.756 | N6: 91119.974 | O6: 31040.87 | P6: 1810.6824 | Q6: 4.3974645 | R6: 0.34065934
A7: 978 | B7: 80 | C7: 45187 | D7: 17 | E7: 5 | F7: 949.1165 | G7: Washing Machine 80 | H7: Home Appliances | I7: 599.442 | J7: 999.07 | K7: 5 | L7: 1039.205 | M7: 4319.1967 | N7: 16134.98 | O7: 5944.4665 | P7: -3370.0802 | Q7: -0.78025624 | R7: 0.36842105
A8: 958 | B8: 116 | C8: 46013 | D8: 11 | E8: 3 | F8: 2292.2555 | G8: Building Blocks 116 | H8: Toys | I8: 1417.89 | J8: 2363.15 | K8: 5 | L8: 2435.5171 | M8: 4469.5 | N8: 25214.811 | O8: 9618.0205 | P8: -2177.2445 | Q8: -0.4871338 | R8: 0.3814433
A9: 955 | B9: 9 | C9: 45960 | D9: 9 | E9: 6 | F9: 2692.019 | G9: Air Conditioner 9 | H9: Home Appliances | I9: 1718.31 | J9: 2863.85 | K9: 5 | L9: 3104.1193 | M9: 6325.17 | N9: 24228.171 | O9: 8763.381 | P9: -3633.151 | Q9: -0.57439579 | R9: 0.36170213
A10: 952 | B10: 9 | C10: 45208 | D10: 7 | E10: 6 | F10: 2692.019 | G10: Air Conditioner 9 | H10: Home Appliances | I10: 1718.31 | J10: 2863.85 | K10: 5 | L10: 3677.4394 | M10: 6325.17 | N10: 18844.133 | O10: 6815.963 | P10: -3633.151 | Q10: -0.57439579 | R10: 0.36170213
A11: 940 | B11: 28 | C11: 45151 | D11: 8 | E11: 2 | F11: 5602.2876 | G11: Water Purifier 28 | H11: Home Appliances | I11: 3429.972 | J11: 5716.62 | K11: 5 | L11: 7385.6346 | M11: 3542.956 | N11: 44818.301 | O11: 17378.525 | P11: 2059.3316 | Q11: 0.58124673 | R11: 0.3877551
A12: 935 | B12: 138 | C12: 45013 | D12: 23 | E12: 2 | F12: 3029.6602 | G12: Running Shoes 138 | H12: Sports | I12: 1854.894 | J12: 3091.49 | K12: 5 | L12: 3619.8342 | M12: 4980.4933 | N12: 69682.185 | O12: 27019.623 | P12: -1950.8331 | Q12: -0.39169476 | R12: 0.3877551
A13: 931 | B13: 141 | C13: 45203 | D13: 40 | E13: 7 | F13: 7314.6267 | G13: Puzzle Set 141 | H13: Toys | I13: 4719.114 | J13: 7865.19 | K13: 5 | L13: 8319.4487 | M13: 7586.8133 | N13: 292585.07 | O13: 103820.51 | P13: -272.18663 | Q13: -0.035876279 | R13: 0.35483871
... A189: 189 | B189: 139 | C189: 45619 | D189: 18 | E189: 3 | F189: 2513.3476 | G189: Jacket 139 | H189: Fashion | I189: 1554.648 | J189: 2591.08 | K189: 5 | L189: 2793.2408 | M189: 2839.1733 | N189: 45240.257 | O189: 17256.593 | P189: -325.82573 | Q189: -0.11476078 | R189: 0.3814433

Sheet Sheet5
A1: sale_id | B1: product_id | C1: sale_date | D1: quantity_sold | E1: discount_percent | F1: final_sale_price | G1: product_name | H1: category | I1: cost_price | J1: base_price | K1: rating | L1: competitor_price | M1: avg_comp_price | N1: Revenue | O1: Profit | P1: Price Difference | Q1: Price Difference % | R1: Profit_margin
A2: 996 | B2: 88 | C2: 45680 | D2: 4 | E2: 5 | F2: 5924.5135 | G2: Tablet 88 | H2: Electronics | I2: 3741.798 | J2: 6236.33 | K2: 5 | L2: 7706.0076 | M2: 4981.505 | N2: 23698.054 | O2: 8730.862 | P2: 943.0085 | Q2: 0.18930193 | R2: 0.36842105
A3: 992 | B3: 28 | C3: 45856 | D3: 35 | E3: 6 | F3: 5373.6228 | G3: Water Purifier 28 | H3: Home Appliances | I3: 3429.972 | J3: 5716.62 | K3: 5 | L3: 6945.0728 | M3: 3542.956 | N3: 188076.8 | O3: 68027.778 | P3: 1830.6668 | Q3: 0.51670605 | R3: 0.36170213
A4: 991 | B4: 135 | C4: 45723 | D4: 6 | E4: 4 | F4: 7468.5216 | G4: Water Purifier 135 | H4: Home Appliances | I4: 4667.826 | J4: 7779.71 | K4: 5 | L4: 9810.9015 | M4: 4172.7833 | N4: 44811.13 | O4: 16804.174 | P4: 3295.7383 | Q4: 0.78981773 | R4: 0.375
A5: 985 | B5: 80 | C5: 45758 | D5: 36 | E5: 6 | F5: 939.1258 | G5: Washing Machine 80 | H5: Home Appliances | I5: 599.442 | J5: 999.07 | K5: 5 | L5: 1235.9662 | M5: 4319.1967 | N5: 33808.529 | O5: 12228.617 | P5: -3380.0709 | Q5: -0.78256934 | R5: 0.36170213
A6: 982 | B6: 61 | C6: 45078 | D6: 41 | E6: 9 | F6: 2222.4384 | G6: Green Tea 61 | H6: Grocery | I6: 1465.344 | J6: 2442.24 | K6: 5 | L6: 2491.9872 | M6: 411.756 | N6: 91119.974 | O6: 31040.87 | P6: 1810.6824 | Q6: 4.3974645 | R6: 0.34065934
A7: 978 | B7: 80 | C7: 45187 | D7: 17 | E7: 5 | F7: 949.1165 | G7: Washing Machine 80 | H7: Home Appliances | I7: 599.442 | J7: 999.07 | K7: 5 | L7: 1039.205 | M7: 4319.1967 | N7: 16134.98 | O7: 5944.4665 | P7: -3370.0802 | Q7: -0.78025624 | R7: 0.36842105
A8: 958 | B8: 116 | C8: 46013 | D8: 11 | E8: 3 | F8: 2292.2555 | G8: Building Blocks 116 | H8: Toys | I8: 1417.89 | J8: 2363.15 | K8: 5 | L8: 2435.5171 | M8: 4469.5 | N8: 25214.811 | O8: 9618.0205 | P8: -2177.2445 | Q8: -0.4871338 | R8: 0.3814433
A9: 955 | B9: 9 | C9: 45960 | D9: 9 | E9: 6 | F9: 2692.019 | G9: Air Conditioner 9 | H9: Home Appliances | I9: 1718.31 | J9: 2863.85 | K9: 5 | L9: 3104.1193 | M9: 6325.17 | N9: 24228.171 | O9: 8763.381 | P9: -3633.151 | Q9: -0.57439579 | R9: 0.36170213
A10: 952 | B10: 9 | C10: 45208 | D10: 7 | E10: 6 | F10: 2692.019 | G10: Air Conditioner 9 | H10: Home Appliances | I10: 1718.31 | J10: 2863.85 | K10: 5 | L10: 3677.4394 | M10: 6325.17 | N10: 18844.133 | O10: 6815.963 | P10: -3633.151 | Q10: -0.57439579 | R10: 0.36170213
A11: 940 | B11: 28 | C11: 45151 | D11: 8 | E11: 2 | F11: 5602.2876 | G11: Water Purifier 28 | H11: Home Appliances | I11: 3429.972 | J11: 5716.62 | K11: 5 | L11: 7385.6346 | M11: 3542.956 | N11: 44818.301 | O11: 17378.525 | P11: 2059.3316 | Q11: 0.58124673 | R11: 0.3877551
A12: 935 | B12: 138 | C12: 45013 | D12: 23 | E12: 2 | F12: 3029.6602 | G12: Running Shoes 138 | H12: Sports | I12: 1854.894 | J12: 3091.49 | K12: 5 | L12: 3619.8342 | M12: 4980.4933 | N12: 69682.185 | O12: 27019.623 | P12: -1950.8331 | Q12: -0.39169476 | R12: 0.3877551
A13: 931 | B13: 141 | C13: 45203 | D13: 40 | E13: 7 | F13: 7314.6267 | G13: Puzzle Set 141 | H13: Toys | I13: 4719.114 | J13: 7865.19 | K13: 5 | L13: 8319.4487 | M13: 7586.8133 | N13: 292585.07 | O13: 103820.51 | P13: -272.18663 | Q13: -0.035876279 | R13: 0.35483871
... A189: 189 | B189: 139 | C189: 45619 | D189: 18 | E189: 3 | F189: 2513.3476 | G189: Jacket 139 | H189: Fashion | I189: 1554.648 | J189: 2591.08 | K189: 5 | L189: 2793.2408 | M189: 2839.1733 | N189: 45240.257 | O189: 17256.593 | P189: -325.82573 | Q189: -0.11476078 | R189: 0.3814433

Sheet Sheet6
A1: sale_id | B1: product_id | C1: sale_date | D1: quantity_sold | E1: discount_percent | F1: final_sale_price | G1: product_name | H1: category | I1: cost_price | J1: base_price | K1: rating | L1: competitor_price | M1: avg_comp_price | N1: Revenue | O1: Profit | P1: Price Difference | Q1: Price Difference % | R1: Profit_margin
A2: 990 | B2: 57 | C2: 45971 | D2: 9 | E2: 2 | F2: 6675.515 | G2: Face Wash 57 | H2: Beauty | I2: 4087.05 | J2: 6811.75 | K2: 2 | L2: 7107.6147 | M2: 1836.9825 | N2: 60079.635 | O2: 23296.185 | P2: 4838.5325 | Q2: 2.6339568 | R2: 0.3877551
A3: 964 | B3: 55 | C3: 45611 | D3: 27 | E3: 4 | F3: 925.7184 | G3: Face Wash 55 | H3: Beauty | I3: 578.574 | J3: 964.29 | K3: 2 | L3: 1239.4157 | M3: 1508.7675 | N3: 24994.397 | O3: 9372.8988 | P3: -583.0491 | Q3: -0.38644065 | R3: 0.375
A4: 957 | B4: 108 | C4: 45305 | D4: 27 | E4: 4 | F4: 806.9184 | G4: Lipstick 108 | H4: Beauty | I4: 504.324 | J4: 840.54 | K4: 3 | L4: 1037.9023 | M4: 5163.712 | N4: 21786.797 | O4: 8170.0488 | P4: -4356.7936 | Q4: -0.84373288 | R4: 0.375
A5: 944 | B5: 108 | C5: 44947 | D5: 41 | E5: 4 | F5: 806.9184 | G5: Lipstick 108 | H5: Beauty | I5: 504.324 | J5: 840.54 | K5: 3 | L5: 989.3084 | M5: 5163.712 | N5: 33083.654 | O5: 12406.37 | P5: -4356.7936 | Q5: -0.84373288 | R5: 0.375
A6: 939 | B6: 39 | C6: 44942 | D6: 22 | E6: 8 | F6: 2950.9736 | G6: Perfume 39 | H6: Beauty | I6: 1924.548 | J6: 3207.58 | K6: 1 | L6: 3636.3627 | M6: 9555.608 | N6: 64921.419 | O6: 22581.363 | P6: -6604.6344 | Q6: -0.69117888 | R6: 0.34782609
A7: 937 | B7: 107 | C7: 45289 | D7: 1 | E7: 7 | F7: 1458.147 | G7: Face Wash 107 | H7: Beauty | I7: 940.74 | J7: 1567.9 | K7: 2 | L7: 1750.7861 | M7: 979.96 | N7: 1458.147 | O7: 517.407 | P7: 478.187 | Q7: 0.48796584 | R7: 0.35483871
A8: 924 | B8: 122 | C8: 45775 | D8: 21 | E8: 8 | F8: 4735.9208 | G8: Shampoo 122 | H8: Beauty | I8: 3088.644 | J8: 5147.74 | K8: 3 | L8: 5996.0351 | M8: 4724.1475 | N8: 99454.337 | O8: 34592.813 | P8: 11.7733 | Q8: 0.0024921533 | R8: 0.34782609
A9: 919 | B9: 111 | C9: 45089 | D9: 11 | E9: 10 | F9: 678.798 | G9: Perfume 111 | H9: Beauty | I9: 452.532 | J9: 754.22 | K9: 3 | L9: 756.41902 | M9: 3824.045 | N9: 7466.778 | O9: 2488.926 | P9: -3145.247 | Q9: -0.82249215 | R9: 0.33333333
A10: 914 | B10: 84 | C10: 45589 | D10: 28 | E10: 6 | F10: 7294.5504 | G10: Moisturizer 84 | H10: Beauty | I10: 4656.096 | J10: 7760.16 | K10: 1 | L10: 10061.558 | M10: 2588.925 | N10: 204247.41 | O10: 73876.723 | P10: 4705.6254 | Q10: 1.8175982 | R10: 0.36170213
A11: 911 | B11: 55 | C11: 45738 | D11: 14 | E11: 3 | F11: 935.3613 | G11: Face Wash 55 | H11: Beauty | I11: 578.574 | J11: 964.29 | K11: 2 | L11: 1041.846 | M11: 1508.7675 | N11: 13095.058 | O11: 4995.0222 | P11: -573.4062 | Q11: -0.38004941 | R11: 0.3814433
A12: 896 | B12: 107 | C12: 45363 | D12: 33 | E12: 3 | F12: 1520.863 | G12: Face Wash 107 | H12: Beauty | I12: 940.74 | J12: 1567.9 | K12: 2 | L12: 1856.823 | M12: 979.96 | N12: 50188.479 | O12: 19144.059 | P12: 540.903 | Q12: 0.55196437 | R12: 0.3814433
A13: 893 | B13: 107 | C13: 45257 | D13: 13 | E13: 2 | F13: 1536.542 | G13: Face Wash 107 | H13: Beauty | I13: 940.74 | J13: 1567.9 | K13: 2 | L13: 1751.6596 | M13: 979.96 | N13: 19975.046 | O13: 7745.426 | P13: 556.582 | Q13: 0.567964 | R13: 0.3877551
... A89: 109 | B89: 83 | C89: 45801 | D89: 32 | E89: 4 | F89: 3663.7728 | G89: Foundation 83 | H89: Beauty | I89: 2289.858 | J89: 3816.43 | K89: 2 | L89: 4469.2281 | M89: 2990.235 | N89: 117240.73 | O89: 43965.274 | P89: 673.5378 | Q89: 0.22524577 | R89: 0.375

Sheet Sheet7
A1: sale_id | B1: product_id | C1: sale_date | D1: quantity_sold | E1: discount_percent | F1: final_sale_price | G1: product_name | H1: category | I1: cost_price | J1: base_price | K1: rating | L1: competitor_price | M1: avg_comp_price | N1: Revenue | O1: Profit | P1: Price Difference | Q1: Price Difference % | R1: Profit_margin
A2: 998 | B2: 34 | C2: 45615 | D2: 35 | E2: 7 | F2: 1212.1527 | G2: Doll 34 | H2: Toys | I2: 782.034 | J2: 1303.39 | K2: 2 | L2: 1355.9981 | M2: 4145.444 | N2: 42425.345 | O2: 15054.155 | P2: -2933.2913 | Q2: -0.707594 | R2: 0.35483871
A3: 995 | B3: 91 | C3: 45975 | D3: 1 | E3: 3 | F3: 3068.11 | G3: Sunglasses 91 | H3: Fashion | I3: 1897.8 | J3: 3163 | K3: 2 | L3: 3609.1711 | M3: 4782.2433 | N3: 3068.11 | O3: 1170.31 | P3: -1714.1333 | Q3: -0.35843708 | R3: 0.3814433
A4: 990 | B4: 57 | C4: 45971 | D4: 9 | E4: 2 | F4: 6675.515 | G4: Face Wash 57 | H4: Beauty | I4: 4087.05 | J4: 6811.75 | K4: 2 | L4: 7107.6147 | M4: 1836.9825 | N4: 60079.635 | O4: 23296.185 | P4: 4838.5325 | Q4: 2.6339568 | R4: 0.3877551
A5: 989 | B5: 91 | C5: 45915 | D5: 33 | E5: 7 | F5: 2941.59 | G5: Sunglasses 91 | H5: Fashion | I5: 1897.8 | J5: 3163 | K5: 2 | L5: 3462.4465 | M5: 4782.2433 | N5: 97072.47 | O5: 34445.07 | P5: -1840.6533 | Q5: -0.38489328 | R5: 0.35483871
A6: 5 | B6: 121 | C6: 45115 | D6: 49 | E6: 6 | F6: 1422.3892 | G6: Self Help Book 121 | H6: Books | I6: 907.908 | J6: 1513.18 | K6: 2 | L6: 1861.0269 | M6: 2967.02 | N6: 69697.071 | O6: 25209.579 | P6: -1544.6308 | Q6: -0.52060006 | R6: 0.36170213
A7: 6 | B7: 101 | C7: 45097 | D7: 48 | E7: 5 | F7: 4484.2755 | G7: Jacket 101 | H7: Fashion | I7: 2832.174 | J7: 4720.29 | K7: 2 | L7: 5898.9923 | M7: 6068.018 | N7: 215245.22 | O7: 79300.872 | P7: -1583.7425 | Q7: -0.26099832 | R7: 0.36842105
A8: 988 | B8: 114 | C8: 45296 | D8: 19 | E8: 4 | F8: 7338.6336 | G8: Smartwatch 114 | H8: Electronics | I8: 4586.646 | J8: 7644.41 | K8: 2 | L8: 8377.3819 | M8: 6494.3075 | N8: 139434.04 | O8: 52287.764 | P8: 844.3261 | Q8: 0.13001018 | R8: 0.375
A9: 976 | B9: 34 | C9: 45708 | D9: 41 | E9: 7 | F9: 1212.1527 | G9: Doll 34 | H9: Toys | I9: 782.034 | J9: 1303.39 | K9: 2 | L9: 1465.5121 | M9: 4145.444 | N9: 49698.261 | O9: 17634.867 | P9: -2933.2913 | Q9: -0.707594 | R9: 0.35483871
A10: 9 | B10: 82 | C10: 45795 | D10: 50 | E10: 4 | F10: 1220.3712 | G10: Yoga Mat 82 | H10: Sports | I10: 762.732 | J10: 1271.22 | K10: 2 | L10: 1619.9944 | M10: 2617.708 | N10: 61018.56 | O10: 22881.96 | P10: -1397.3368 | Q10: -0.53380163 | R10: 0.375
A11: 970 | B11: 120 | C11: 45565 | D11: 22 | E11: 6 | F11: 1858.004 | G11: Vacuum Cleaner 120 | H11: Home Appliances | I11: 1185.96 | J11: 1976.6 | K11: 2 | L11: 2485.5667 | M11: 1688.8575 | N11: 40876.088 | O11: 14784.968 | P11: 169.1465 | Q11: 0.10015439 | R11: 0.36170213
A12: 964 | B12: 55 | C12: 45611 | D12: 27 | E12: 4 | F12: 925.7184 | G12: Face Wash 55 | H12: Beauty | I12: 578.574 | J12: 964.29 | K12: 2 | L12: 1239.4157 | M12: 1508.7675 | N12: 24994.397 | O12: 9372.8988 | P12: -583.0491 | Q12: -0.38644065 | R12: 0.375
A13: 963 | B13: 106 | C13: 45197 | D13: 22 | E13: 10 | F13: 1290.627 | G13: Doll 106 | H13: Toys | I13: 860.418 | J13: 1434.03 | K13: 2 | L13: 1438.5138 | M13: 695.384 | N13: 28393.794 | O13: 9464.598 | P13: 595.243 | Q13: 0.8559918 | R13: 0.33333333
... A231: 235 | B231: 68 | C231: 45980 | D231: 17 | E231: 3 | F231: 5862.1853 | G231: Lipstick 68 | H231: Beauty | I231: 3626.094 | J231: 6043.49 | K231: 2 | L231: 6445.1162 | M231: 796.21333 | N231: 99657.15 | O231: 38013.552 | P231: 5065.972 | Q231: 6.3625812 | R231: 0.3814433

Sheet Dashboard

Sheet Pivot_tbl
A2: Top Products by Revenue | D2: Total Revenue by Category | G2: Profit by Category | J2: Avg Rating by Category | M2: Sales Contribution by Category | P2: Low Performance Products
A4: product_name | B4: Sum of Revenue | D4: category | E4: Sum of Revenue | G4: category | H4: Sum of Profit | J4: category | K4: Average of rating | M4: category | N4: Count of quantity_sold | P4: product_name | Q4: Sum of Revenue
A5: Coffee Beans 18 | B5: 1581825 | D5: Beauty | E5: 6825576.2 | G5: Beauty | H5: 0.078133835 | J5: Beauty | K5: 2.4090909 | M5: Beauty | N5: 88 | P5: Action Figure 42 | Q5: 42717.24
A6: Cookbook 93 | B6: 1672585.8 | D6: Books | E6: 12553509 | G6: Books | H6: 0.14302176 | J6: Books | K6: 2.7762238 | M6: Books | N6: 143 | P6: Coffee Beans 44 | Q6: 45363.344
A7: Handbag 7 | B7: 1521222.5 | D7: Electronics | E7: 12715150 | G7: Electronics | H7: 0.14570776 | J7: Electronics | K7: 3.0377358 | M7: Electronics | N7: 106 | P7: Dress 40 | Q7: 55862.8
A8: Laptop 87 | B8: 1471877.1 | D8: Fashion | E8: 10136043 | G8: Fashion | H8: 0.11634171 | J8: Fashion | K8: 2.704 | M8: Fashion | N8: 125 | P8: Gym Gloves 148 | Q8: 3948.4396
A9: Puzzle Set 141 | B9: 2194859.9 | D9: Grocery | E9: 10870392 | G9: Grocery | H9: 0.12431987 | J9: Grocery | K9: 2.725 | M9: Grocery | N9: 120 | P9: Headphones 134 | Q9: 60075.408
A10: Puzzle Set 8 | B10: 1423853.2 | D10: Home Appliances | E10: 11792265 | G10: Home Appliances | H10: 0.13465013 | J10: Home Appliances | K10: 3.5 | M10: Home Appliances | N10: 154 | P10: Moisturizer 137 | Q10: 38973.082
A11: Smartphone 149 | B11: 1672271.2 | D11: Sports | E11: 8099913.9 | G11: Sports | H11: 0.093168325 | J11: Sports | K11: 3.0679612 | M11: Sports | N11: 103 | P11: Refrigerator 36 | Q11: 45699.896
A12: Smartwatch 114 | B12: 1833206 | D12: Toys | E12: 14339663 | G12: Toys | H12: 0.16465661 | J12: Toys | K12: 3.0745342 | M12: Toys | N12: 161 | P12: Remote Car 143 | Q12: 7642.3805
A13: Smartwatch 56 | B13: 1995928.9 | D13: (blank) | G13: (blank) | H13: 0 | M13: (blank) | P13: Sneakers 35 | Q13: 31946.749
A14: Water Purifier 28 | B14: 1763920.3 | P14: (blank)
AA15: =GETPIVOTDATA("Revenue",$AA$17) -> 87332512 | AD15: =GETPIVOTDATA("Profit",$AD$17) -> 31497339 | AG15: =GETPIVOTDATA("rating ",$AG$17) -> 2.946 | AI15: =GETPIVOTDATA("discount_percent",$AI$17) -> 6.099 | AK15: Row Labels | AL15: Sum of Profit | AM15: Sum of Revenue
AK16: (blank)
AA17: Sum of Revenue | AD17: Sum of Profit | AG17: Avg of rating | AI17: Avg of discount_percent | AK17: Jan | AL17: 2769767.1 | AM17: 7743648.1 | AP17: Sum of Revenue | AQ17: Column Labels
AA18: 87332512 | AD18: 31497339 | AG18: 2.946 | AI18: 6.099 | AK18: Feb | AL18: 2649894.5 | AM18: 7330432.2 | AP18: Row Labels | AQ18: Beauty | AR18: Books | AS18: Electronics | AT18: Fashion | AU18: Grocery | AV18: Home Appliances | AW18: Sports | AX18: Toys | AY18: Grand Total
A19: Our Price vs Competitor Price | E19: Monthly Revenue Trend | I19: Avg Discount vs Revenue | M19: Customer Satisfication vs Profit | AK19: Mar | AL19: 2428541.7 | AM19: 6748753.1 | AP19: 2023
AK20: Apr | AL20: 2896754.2 | AM20: 8062264.1 | AP20: Jan | AQ20: 259187.01 | AR20: 1029218.7 | AS20: 275668.61 | AT20: 285017.62 | AU20: 475109.33 | AW20: 372363.65 | AX20: 225987.2 | AY20: 2922552.1
A21: product_name | B21: Avg of final_sale_price | C21: avg_comp_price | E21: Years | F21: sale_date | G21: Sum of Revenue | I21: product_name | J21: Avg of discount_percent | K21: Sum of Revenue | M21: rating | N21: Sum of Profit | AK21: May | AL21: 1982666.1 | AM21: 5496969.3 | AP21: Feb | AQ21: 106142.92 | AR21: 656934.13 | AS21: 163501.89 | AT21: 125059.94 | AU21: 95382.198 | AV21: 573849.01 | AW21: 394402.32 | AX21: 444698 | AY21: 2559970.4
A22: Action Figure 102 | B22: 3881.4905 | C22: 2740.84 | E22: 2023 | F22: Jan | G22: 2922552.1 | I22: Action Figure 102 | J22: 6.3333333 | K22: 492010 | M22: 1 | N22: 5812228 | AK22: Jun | AL22: 3002222.9 | AM22: 8331287.6 | AP22: Mar | AQ22: 194082.01 | AR22: 646617.39 | AT22: 144672.05 | AU22: 166476.98 | AV22: 456839.46 | AW22: 386853.45 | AX22: 265322.85 | AY22: 2260864.2
A23: Action Figure 105 | B23: 3977.3568 | C23: 4778.885 | F23: Feb | G23: 2559970.4 | I23: Action Figure 105 | J23: 4 | K23: 485154.67 | M23: 2 | N23: 7270348.6 | AK23: Jul | AL23: 2524592.4 | AM23: 7000676.1 | AP23: Apr | AQ23: 47970.345 | AR23: 695733.31 | AS23: 276122.12 | AT23: 41206.637 | AU23: 25200.244 | AV23: 899649.73 | AW23: 777149.25 | AX23: 369038.31 | AY23: 3132069.9
A24: Action Figure 27 | B24: 1545.8123 | C24: 4440.4167 | F24: Mar | G24: 2260864.2 | I24: Action Figure 27 | J24: 4.75 | K24: 169755.34 | M24: 3 | N24: 5989084.1 | AK24: Aug | AL24: 2689529.9 | AM24: 7422425.8 | AP24: May | AQ24: 28745.533 | AR24: 417647.79 | AS24: 478925.73 | AT24: 87146.49 | AU24: 394246.73 | AV24: 193620.39 | AW24: 117820.96 | AX24: 446421.79 | AY24: 2164575.4
A25: Action Figure 42 | B25: 408.7856 | C25: 513.45667 | F25: Apr | G25: 3132069.9 | I25: Action Figure 42 | J25: 4.4 | K25: 42717.24 | M25: 4 | N25: 5907714.6 | AK25: Sep | AL25: 1615677.8 | AM25: 4435348.1 | AP25: Jun | AQ25: 65203.218 | AR25: 60877.032 | AS25: 88425.742 | AT25: 339117.56 | AU25: 660910.51 | AV25: 298568.12 | AW25: 415114.89 | AX25: 207462.89 | AY25: 2135680
A26: Action Figure 46 | B26: 1505.3538 | C26: 4497.678 | F26: May | G26: 2164575.4 | I26: Action Figure 46 | J26: 7 | K26: 211834.03 | M26: 5 | N26: 6517963.7 | AK26: Oct | AL26: 3585977.7 | AM26: 9870492.3 | AP26: Jul | AQ26: 117020.06 | AR26: 279875.01 | AS26: 504639.8 | AT26: 401889.05 | AU26: 359560.17 | AV26: 707642.5 | AW26: 160815.43 | AX26: 399624.68 | AY26: 2931066.7
A27: Action Figure 73 | B27: 4218.0987 | C27: 5380.9517 | F27: Jun | G27: 2135680 | I27: Action Figure 73 | J27: 7 | K27: 289824.2 | AK27: Nov | AL27: 2480683.4 | AM27: 6791752 | AP27: Aug | AQ27: 12555.056 | AR27: 404185.29 | AS27: 750429.3 | AU27: 512832.69 | AV27: 561583.81 | AW27: 320416.94 | AX27: 22367.873 | AY27: 2584370.9
A28: Air Conditioner 125 | B28: 4060.9987 | C28: 5094.804 | F28: Jul | G28: 2931066.7 | I28: Air Conditioner 125 | J28: 6.6666667 | K28: 1027505.2 | AK28: Dec | AL28: 2871031.2 | AM28: 8098463.3 | AP28: Sep | AR28: 504722.85 | AS28: 117085.89 | AT28: 52035.731 | AU28: 377735.69 | AV28: 84085.182 | AW28: 262939.07 | AX28: 77140.574 | AY28: 1475745
A29: Air Conditioner 144 | B29: 1494.5743 | C29: 6414.024 | F29: Aug | G29: 2584370.9 | I29: Air Conditioner 144 | J29: 5.3 | K29: 415466.41 | AK29: Grand Total | AL29: 31497339 | AM29: 87332512 | AP29: Oct | AQ29: 386350.36 | AR29: 572816.3 | AS29: 1112705.7 | AT29: 307223.56 | AU29: 271562.07 | AV29: 366014.3 | AW29: 135991.34 | AX29: 408976.4 | AY29: 3561640
A30: Air Conditioner 19 | B30: 3189.126 | C30: 1213.8383 | F30: Sep | G30: 1475745 | I30: Air Conditioner 19 | J30: 6.5 | K30: 375088.98 | AP30: Nov | AQ30: 175143.11 | AR30: 390239.22 | AS30: 115810.27 | AT30: 564436.92 | AU30: 461469.44 | AV30: 224688 | AX30: 149919.31 | AY30: 2081706.3
A31: Air Conditioner 2 | B31: 4083.4398 | C31: 1807.3 | F31: Oct | G31: 3561640 | I31: Air Conditioner 2 | J31: 7.7142857 | K31: 816150.67 | AP31: Dec | AQ31: 156939.01 | AR31: 621038.31 | AS31: 79043.199 | AT31: 213848.08 | AU31: 493503.5 | AW31: 57391.578 | AX31: 1092132.4 | AY31: 2713896.1
A32: Air Conditioner 9 | B32: 2709.9181 | C32: 6325.17 | F32: Nov | G32: 2081706.3 | I32: Air Conditioner 9 | J32: 5.375 | K32: 336846.04 | AP32: 2024
A33: Biography 3 | B33: 4830.9393 | C33: 7049.42 | F33: Dec | G33: 2713896.1 | I33: Biography 3 | J33: 6.5 | K33: 634170.58 | AP33: Jan | AQ33: 197150.04 | AR33: 502400.3 | AS33: 452657.67 | AT33: 18568.424 | AU33: 182542.25 | AV33: 430097.04 | AW33: 491805.69 | AX33: 808898.39 | AY33: 3084119.8
A34: Biography 60 | B34: 2566.2046 | C34: 3047.7533 | E34: 2024 | F34: Jan | G34: 3084119.8 | I34: Biography 60 | J34: 7.4444444 | K34: 521389.31 | AP34: Feb | AQ34: 66879.864 | AR34: 221360.24 | AS34: 631655.41 | AT34: 128914.58 | AU34: 610394.14 | AV34: 192352.26 | AW34: 75655.387 | AX34: 202966.47 | AY34: 2130178.4
A35: Biography 65 | B35: 4270.7541 | C35: 1786.8475 | F35: Feb | G35: 2130178.4 | I35: Biography 65 | J35: 5.3333333 | K35: 661184.92 | AP35: Mar | AQ35: 305298.6 | AR35: 192287.07 | AS35: 99656.553 | AT35: 140169.26 | AU35: 56064.028 | AV35: 242971.99 | AW35: 246662.44 | AX35: 204082.41 | AY35: 1487192.3
A36: Biography 78 | B36: 814.58264 | C36: 398.392 | F36: Mar | G36: 1487192.3 | I36: Biography 78 | J36: 5.9090909 | K36: 216054.07 | AP36: Apr | AQ36: 343706.19 | AR36: 16121.216 | AS36: 378297.31 | AT36: 650877.56 | AU36: 389726.53 | AV36: 170727.47 | AW36: 495513.57 | AX36: 185042.19 | AY36: 2630012
A37: Biography 79 | B37: 2060.7347 | C37: 197.005 | F37: Apr | G37: 2630012 | I37: Biography 79 | J37: 6.6666667 | K37: 247111.53 | AP37: May | AQ37: 327715.2 | AS37: 419942.58 | AT37: 375300.2 | AU37: 30717.33 | AV37: 49188.202 | AX37: 604223.49 | AY37: 1807087
A38: Bluetooth Speaker 23 | B38: 3781.0836 | C38: 5343.328 | F38: May | G38: 1807087 | I38: Bluetooth Speaker 23 | J38: 4.6 | K38: 424995.38 | AP38: Jun | AQ38: 13676.087 | AR38: 157894.45 | AS38: 977502.6 | AT38: 357205.76 | AU38: 822971.81 | AV38: 559878.12 | AW38: 111148.61 | AX38: 307817.73 | AY38: 3308095.2
A39: Bluetooth Speaker 31 | B39: 946.497 | C39: 1065.822 | F39: Jun | G39: 3308095.2 | I39: Bluetooth Speaker 31 | J39: 7.5 | K39: 190281.71 | AP39: Jul | AQ39: 6083.452 | AR39: 237192.95 | AS39: 244243.08 | AT39: 84883.781 | AU39: 167760.29 | AV39: 409685.36 | AW39: 95730.063 | AX39: 235259.02 | AY39: 1480838
A40: Bluetooth Speaker 51 | B40: 958.1117 | C40: 5383.6833 | F40: Jul | G40: 1480838 | I40: Bluetooth Speaker 51 | J40: 9 | K40: 61898.227 | AP40: Aug | AQ40: 381413.15 | AR40: 673886.99 | AS40: 11533.494 | AT40: 542634.76 | AU40: 550905.95 | AV40: 302297.25 | AW40: 226512.51 | AX40: 530869.32 | AY40: 3220053.4
A41: Building Blocks 116 | B41: 2207.8573 | C41: 4469.5 | F41: Aug | G41: 3220053.4 | I41: Building Blocks 116 | J41: 6.5714286 | K41: 383775.56 | AP41: Sep | AQ41: 17588.65 | AR41: 58030.727 | AS41: 33306.462 | AT41: 119842.93 | AU41: 32154.055 | AV41: 42645.637 | AW41: 209044.99 | AX41: 240992.94 | AY41: 753606.39
A42: Building Blocks 86 | B42: 2923.0438 | C42: 2919.076 | F42: Sep | G42: 753606.39 | I42: Building Blocks 86 | J42: 6.4 | K42: 279531.67 | AP42: Oct | AQ42: 266828.45 | AR42: 330033.57 | AS42: 277626.02 | AT42: 577488.12 | AU42: 25273.843 | AV42: 326823.57 | AW42: 431893.53 | AX42: 170407.32 | AY42: 2406374.4
...

Sheet Master_tbl
A1: sale_id | B1: product_id | C1: sale_date | D1: quantity_sold | E1: discount_percent | F1: final_sale_price | G1: product_name | H1: category | I1: cost_price | J1: base_price | K1: rating | L1: competitor_price | M1: avg_comp_price | N1: Revenue | O1: Profit | P1: Price Difference | Q1: Price Difference % | R1: Profit_margin
A2: 1 | B2: 90 | C2: 45878 | D2: 12 | E2: 4 | F2: =J2*(1-E2/100) -> 1321.6416 | G2: =VLOOKUP(B2,product_tbl[],2,FALSE) -> Washing Machine 90 | H2: =VLOOKUP(B2,product_tbl[],3,FALSE) -> Home Appliances | I2: 826.026 | J2: =VLOOKUP(B2,product_tbl[],5,FALSE) -> 1376.71 | K2: =VLOOKUP(B2,review_tbl[],3,FALSE) -> 4 | L2: 1699.0295 | M2: =AVERAGEIF(Table1[product_id],Master_tbl!B2:B1001,Table1[competitor_price]) -> 2414.755 | N2: =IFERROR(Table5[[#This Row],[final_sale_price]]*Table5[[#This Row],[quantity_sold ]],0) -> 15859.699 | O2: =(Table5[[#This Row],[final_sale_price]]-Table5[[#This Row],[cost_price]])*Table5[[#This Row],[quantity_sold ]] -> 5947.3872 | P2: =(Table5[final_sale_price]-Table5[[#This Row],[avg_comp_price]]) -> -1093.1134 | Q2: =(Table5[[#This Row],[final_sale_price]]-Table5[[#This Row],[avg_comp_price]])/Table5[[#This Row],[avg_comp_price]] -> -0.45268087 | R2: =Table5[[#This Row],[Profit]]/Table5[[#This Row],[Revenue]] -> 0.375
A3: 2 | B3: 117 | C3: 45372 | D3: 35 | E3: 2 | F3: =J3*(1-E3/100) -> 2084.6364 | G3: =VLOOKUP(B3,product_tbl[],2,FALSE) -> Refrigerator 117 | H3: =VLOOKUP(B3,product_tbl[],3,FALSE) -> Home Appliances | I3: 1276.308 | J3: =VLOOKUP(B3,product_tbl[],5,FALSE) -> 2127.18 | K3: =VLOOKUP(B3,review_tbl[],3,FALSE) -> 1 | L3: 2180.6767 | M3: =AVERAGEIF(Table1[product_id],Master_tbl!B3:B1004,Table1[competitor_price]) -> 892.97667 | N3: =IFERROR(Table5[[#This Row],[final_sale_price]]*Table5[[#This Row],[quantity_sold ]],0) -> 72962.274 | O3: =(Table5[[#This Row],[final_sale_price]]-Table5[[#This Row],[cost_price]])*Table5[[#This Row],[quantity_sold ]] -> 28291.494 | P3: =(Table5[final_sale_price]-Table5[[#This Row],[avg_comp_price]]) -> 1191.6597 | Q3: =(Table5[[#This Row],[final_sale_price]]-Table5[[#This Row],[avg_comp_price]])/Table5[[#This Row],[avg_comp_price]] -> 1.3344803 | R3: =Table5[[#This Row],[Profit]]/Table5[[#This Row],[Revenue]] -> 0.3877551
A4: 3 | B4: 27 | C4: 45339 | D4: 14 | E4: 2 | F4: =J4*(1-E4/100) -> 1590.442 | G4: =VLOOKUP(B4,product_tbl[],2,FALSE) -> Action Figure 27 | H4: =VLOOKUP(B4,product_tbl[],3,FALSE) -> Toys | I4: 973.74 | J4: =VLOOKUP(B4,product_tbl[],5,FALSE) -> 1622.9 | K4: =VLOOKUP(B4,review_tbl[],3,FALSE) -> 1 | L4: 1917.2436 | M4: =AVERAGEIF(Table1[product_id],Master_tbl!B4:B1005,Table1[competitor_price]) -> 4440.4167 | N4: =IFERROR(Table5[[#This Row],[final_sale_price]]*Table5[[#This Row],[quantity_sold ]],0) -> 22266.188 | O4: =(Table5[[#This Row],[final_sale_price]]-Table5[[#This Row],[cost_price]])*Table5[[#This Row],[quantity_sold ]] -> 8633.828 | P4: =(Table5[final_sale_price]-Table5[[#This Row],[avg_comp_price]]) -> -2849.9747 | Q4: =(Table5[[#This Row],[final_sale_price]]-Table5[[#This Row],[avg_comp_price]])/Table5[[#This Row],[avg_comp_price]] -> -0.64182595 | R4: =Table5[[#This Row],[Profit]]/Table5[[#This Row],[Revenue]] -> 0.3877551
A5: 4 | B5: 48 | C5: 45660 | D5: 9 | E5: 3 | F5: =J5*(1-E5/100) -> 3577.6219 | G5: =VLOOKUP(B5,product_tbl[],2,FALSE) -> Water Purifier 48 | H5: =VLOOKUP(B5,product_tbl[],3,FALSE) -> Home Appliances | I5: 2212.962 | J5: =VLOOKUP(B5,product_tbl[],5,FALSE) -> 3688.27 | K5: =VLOOKUP(B5,review_tbl[],3,FALSE) -> 4 | L5: 4431.3786 | M5: =AVERAGEIF(Table1[product_id],Master_tbl!B5:B1006,Table1[competitor_price]) -> 1050.3625 | N5: =IFERROR(Table5[[#This Row],[final_sale_price]]*Table5[[#This Row],[quantity_sold ]],0) -> 32198.597 | O5: =(Table5[[#This Row],[final_sale_price]]-Table5[[#This Row],[cost_price]])*Table5[[#This Row],[quantity_sold ]] -> 12281.939 | P5: =(Table5[final_sale_price]-Table5[[#This Row],[avg_comp_price]]) -> 2527.2594 | Q5: =(Table5[[#This Row],[final_sale_price]]-Table5[[#This Row],[avg_comp_price]])/Table5[[#This Row],[avg_comp_price]] -> 2.406083 | R5: =Table5[[#This Row],[Profit]]/Table5[[#This Row],[Revenue]] -> 0.3814433
A6: 5 | B6: 121 | C6: 45115 | D6: 49 | E6: 6 | F6: =J6*(1-E6/100) -> 1422.3892 | G6: =VLOOKUP(B6,product_tbl[],2,FALSE) -> Self Help Book 121 | H6: =VLOOKUP(B6,product_tbl[],3,FALSE) -> Books | I6: 907.908 | J6: =VLOOKUP(B6,product_tbl[],5,FALSE) -> 1513.18 | K6: =VLOOKUP(B6,review_tbl[],3,FALSE) -> 2 | L6: 1861.0269 | M6: =AVERAGEIF(Table1[product_id],Master_tbl!B6:B1007,Table1[competitor_price]) -> 2967.02 | N6: =IFERROR(Table5[[#This Row],[final_sale_price]]*Table5[[#This Row],[quantity_sold ]],0) -> 69697.071 | O6: =(Table5[[#This Row],[final_sale_price]]-Table5[[#This Row],[cost_price]])*Table5[[#This Row],[quantity_sold ]] -> 25209.579 | P6: =(Table5[final_sale_price]-Table5[[#This Row],[avg_comp_price]]) -> -1544.6308 | Q6: =(Table5[[#This Row],[final_sale_price]]-Table5[[#This Row],[avg_comp_price]])/Table5[[#This Row],[avg_comp_price]] -> -0.52060006 | R6: =Table5[[#This Row],[Profit]]/Table5[[#This Row],[Revenue]] -> 0.36170213
A7: 6 | B7: 101 | C7: 45097 | D7: 48 | E7: 5 | F7: =J7*(1-E7/100) -> 4484.2755 | G7: =VLOOKUP(B7,product_tbl[],2,FALSE) -> Jacket 101 | H7: =VLOOKUP(B7,product_tbl[],3,FALSE) -> Fashion | I7: 2832.174 | J7: =VLOOKUP(B7,product_tbl[],5,FALSE) -> 4720.29 | K7: =VLOOKUP(B7,review_tbl[],3,FALSE) -> 2 | L7: 5898.9923 | M7: =AVERAGEIF(Table1[product_id],Master_tbl!B7:B1008,Table1[competitor_price]) -> 6068.018 | N7: =IFERROR(Table5[[#This Row],[final_sale_price]]*Table5[[#This Row],[quantity_sold ]],0) -> 215245.22 | O7: =(Table5[[#This Row],[final_sale_price]]-Table5[[#This Row],[cost_price]])*Table5[[#This Row],[quantity_sold ]] -> 79300.872 | P7: =(Table5[final_sale_price]-Table5[[#This Row],[avg_comp_price]]) -> -1583.7425 | Q7: =(Table5[[#This Row],[final_sale_price]]-Table5[[#This Row],[avg_comp_price]])/Table5[[#This Row],[avg_comp_price]] -> -0.26099832 | R7: =Table5[[#This Row],[Profit]]/Table5[[#This Row],[Revenue]] -> 0.36842105
A8: 7 | B8: 117 | C8: 45411 | D8: 47 | E8: 2 | F8: =J8*(1-E8/100) -> 2084.6364 | G8: =VLOOKUP(B8,product_tbl[],2,FALSE) -> Refrigerator 117 | H8: =VLOOKUP(B8,product_tbl[],3,FALSE) -> Home Appliances | I8: 1276.308 | J8: =VLOOKUP(B8,product_tbl[],5,FALSE) -> 2127.18 | K8: =VLOOKUP(B8,review_tbl[],3,FALSE) -> 1 | L8: 2707.9822 | M8: =AVERAGEIF(Table1[product_id],Master_tbl!B8:B1009,Table1[competitor_price]) -> 892.97667 | N8: =IFERROR(Table5[[#This Row],[final_sale_price]]*Table5[[#This Row],[quantity_sold ]],0) -> 97977.911 | O8: =(Table5[[#This Row],[final_sale_price]]-Table5[[#This Row],[cost_price]])*Table5[[#This Row],[quantity_sold ]] -> 37991.435 | P8: =(Table5[final_sale_price]-Table5[[#This Row],[avg_comp_price]]) -> 1191.6597 | Q8: =(Table5[[#This Row],[final_sale_price]]-Table5[[#This Row],[avg_comp_price]])/Table5[[#This Row],[avg_comp_price]] -> 1.3344803 | R8: =Table5[[#This Row],[Profit]]/Table5[[#This Row],[Revenue]] -> 0.3877551
A9: 8 | B9: 22 | C9: 45215 | D9: 5 | E9: 10 | F9: =J9*(1-E9/100) -> 1471.05 | G9: =VLOOKUP(B9,product_tbl[],2,FALSE) -> Dress 22 | H9: =VLOOKUP(B9,product_tbl[],3,FALSE) -> Fashion | I9: 980.7 | J9: =VLOOKUP(B9,product_tbl[],5,FALSE) -> 1634.5 | K9: =VLOOKUP(B9,review_tbl[],3,FALSE) -> 1 | L9: 2000.6675 | M9: =AVERAGEIF(Table1[product_id],Master_tbl!B9:B1010,Table1[competitor_price]) -> 3187.445 | N9: =IFERROR(Table5[[#This Row],[final_sale_price]]*Table5[[#This Row],[quantity_sold ]],0) -> 7355.25 | O9: =(Table5[[#This Row],[final_sale_price]]-Table5[[#This Row],[cost_price]])*Table5[[#This Row],[quantity_sold ]] -> 2451.75 | P9: =(Table5[final_sale_price]-Table5[[#This Row],[avg_comp_price]]) -> -1716.395 | Q9: =(Table5[[#This Row],[final_sale_price]]-Table5[[#This Row],[avg_comp_price]])/Table5[[#This Row],[avg_comp_price]] -> -0.53848615 | R9: =Table5[[#This Row],[Profit]]/Table5[[#This Row],[Revenue]] -> 0.33333333
A10: 9 | B10: 82 | C10: 45795 | D10: 50 | E10: 4 | F10: =J10*(1-E10/100) -> 1220.3712 | G10: =VLOOKUP(B10,product_tbl[],2,FALSE) -> Yoga Mat 82 | H10: =VLOOKUP(B10,product_tbl[],3,FALSE) -> Sports | I10: 762.732 | J10: =VLOOKUP(B10,product_tbl[],5,FALSE) -> 1271.22 | K10: =VLOOKUP(B10,review_tbl[],3,FALSE) -> 2 | L10: 1619.9944 | M10: =AVERAGEIF(Table1[product_id],Master_tbl!B10:B1011,Table1[competitor_price]) -> 2617.708 | N10: =IFERROR(Table5[[#This Row],[final_sale_price]]*Table5[[#This Row],[quantity_sold ]],0) -> 61018.56 | O10: =(Table5[[#This Row],[final_sale_price]]-Table5[[#This Row],[cost_price]])*Table5[[#This Row],[quantity_sold ]] -> 22881.96 | P10: =(Table5[final_sale_price]-Table5[[#This Row],[avg_comp_price]]) -> -1397.3368 | Q10: =(Table5[[#This Row],[final_sale_price]]-Table5[[#This Row],[avg_comp_price]])/Table5[[#This Row],[avg_comp_price]] -> -0.53380163 | R10: =Table5[[#This Row],[Profit]]/Table5[[#This Row],[Revenue]] -> 0.375
A11: 10 | B11: 94 | C11: 45067 | D11: 16 | E11: 5 | F11: =J11*(1-E11/100) -> 4420.141 | G11: =VLOOKUP(B11,product_tbl[],2,FALSE) -> Cricket Bat 94 | H11: =VLOOKUP(B11,product_tbl[],3,FALSE) -> Sports | I11: 2791.668 | J11: =VLOOKUP(B11,product_tbl[],5,FALSE) -> 4652.78 | K11: =VLOOKUP(B11,review_tbl[],3,FALSE) -> 1 | L11: 6003.6872 | M11: =AVERAGEIF(Table1[product_id],Master_tbl!B11:B1012,Table1[competitor_price]) -> 6485.5883 | N11: =IFERROR(Table5[[#This Row],[final_sale_price]]*Table5[[#This Row],[quantity_sold ]],0) -> 70722.256 | O11: =(Table5[[#This Row],[final_sale_price]]-Table5[[#This Row],[cost_price]])*Table5[[#This Row],[quantity_sold ]] -> 26055.568 | P11: =(Table5[final_sale_price]-Table5[[#This Row],[avg_comp_price]]) -> -2065.4473 | Q11: =(Table5[[#This Row],[final_sale_price]]-Table5[[#This Row],[avg_comp_price]])/Table5[[#This Row],[avg_comp_price]] -> -0.31846723 | R11: =Table5[[#This Row],[Profit]]/Table5[[#This Row],[Revenue]] -> 0.36842105
A12: 11 | B12: 40 | C12: 45755 | D12: 3 | E12: 7 | F12: =J12*(1-E12/100) -> 457.8111 | G12: =VLOOKUP(B12,product_tbl[],2,FALSE) -> Dress 40 | H12: =VLOOKUP(B12,product_tbl[],3,FALSE) -> Fashion | I12: 295.362 | J12: =VLOOKUP(B12,product_tbl[],5,FALSE) -> 492.27 | K12: =VLOOKUP(B12,review_tbl[],3,FALSE) -> 1 | L12: 564.49763 | M12: =AVERAGEIF(Table1[product_id],Master_tbl!B12:B1013,Table1[competitor_price]) -> 603.706 | N12: =IFERROR(Table5[[#This Row],[final_sale_price]]*Table5[[#This Row],[quantity_sold ]],0) -> 1373.4333 | O12: =(Table5[[#This Row],[final_sale_price]]-Table5[[#This Row],[cost_price]])*Table5[[#This Row],[quantity_sold ]] -> 487.3473 | P12: =(Table5[final_sale_price]-Table5[[#This Row],[avg_comp_price]]) -> -145.8949 | Q12: =(Table5[[#This Row],[final_sale_price]]-Table5[[#This Row],[avg_comp_price]])/Table5[[#This Row],[avg_comp_price]] -> -0.24166548 | R12: =Table5[[#This Row],[Profit]]/Table5[[#This Row],[Revenue]] -> 0.35483871
A13: 12 | B13: 50 | C13: 45784 | D13: 47 | E13: 9 | F13: =J13*(1-E13/100) -> 1234.597 | G13: =VLOOKUP(B13,product_tbl[],2,FALSE) -> Doll 50 | H13: =VLOOKUP(B13,product_tbl[],3,FALSE) -> Toys | I13: 814.02 | J13: =VLOOKUP(B13,product_tbl[],5,FALSE) -> 1356.7 | K13: =VLOOKUP(B13,review_tbl[],3,FALSE) -> 3 | L13: 1594.9775 | M13: =AVERAGEIF(Table1[product_id],Master_tbl!B13:B1014,Table1[competitor_price]) -> 4909.6483 | N13: =IFERROR(Table5[[#This Row],[final_sale_price]]*Table5[[#This Row],[quantity_sold ]],0) -> 58026.059 | O13: =(Table5[[#This Row],[final_sale_price]]-Table5[[#This Row],[cost_price]])*Table5[[#This Row],[quantity_sold ]] -> 19767.119 | P13: =(Table5[final_sale_price]-Table5[[#This Row],[avg_comp_price]]) -> -3675.0513 | Q13: =(Table5[[#This Row],[final_sale_price]]-Table5[[#This Row],[avg_comp_price]])/Table5[[#This Row],[avg_comp_price]] -> -0.74853657 | R13: =Table5[[#This Row],[Profit]]/Table5[[#This Row],[Revenue]] -> 0.34065934
A14: 13 | B14: 32 | C14: 45377 | D14: 28 | E14: 4 | F14: =J14*(1-E14/100) -> 911.0016 | G14: =VLOOKUP(B14,product_tbl[],2,FALSE) -> Fiction Novel 32 | H14: =VLOOKUP(B14,product_tbl[],3,FALSE) -> Books | I14: 569.376 | J14: =VLOOKUP(B14,product_tbl[],5,FALSE) -> 948.96 | K14: =VLOOKUP(B14,review_tbl[],3,FALSE) -> 4 | L14: 1086.3976 | M14: =AVERAGEIF(Table1[product_id],Master_tbl!B14:B1015,Table1[competitor_price]) -> 2168.4867 | N14: =IFERROR(Table5[[#This Row],[final_sale_price]]*Table5[[#This Row],[quantity_sold ]],0) -> 25508.045 | O14: =(Table5[[#This Row],[final_sale_price]]-Table5[[#This Row],[cost_price]])*Table5[[#This Row],[quantity_sold ]] -> 9565.5168 | P14: =(Table5[final_sale_price]-Table5[[#This Row],[avg_comp_price]]) -> -1257.4851 | Q14: =(Table5[[#This Row],[final_sale_price]]-Table5[[#This Row],[avg_comp_price]])/Table5[[#This Row],[avg_comp_price]] -> -0.57989061 | R14: =Table5[[#This Row],[Profit]]/Table5[[#This Row],[Revenue]] -> 0.375
... A1001: 1000 | B1001: 134 | C1001: 45675 | D1001: 17 | E1001: 5 | F1001: =J1001*(1-E1001/100) -> 638.5995 | G1001: =VLOOKUP(B1001,product_tbl[],2,FALSE) -> Headphones 134 | H1001: =VLOOKUP(B1001,product_tbl[],3,FALSE) -> Electronics | I1001: 403.326 | J1001: =VLOOKUP(B1001,product_tbl[],5,FALSE) -> 672.21 | K1001: =VLOOKUP(B1001,review_tbl[],3,FALSE) -> 1 | L1001: 703.02475 | M1001: =AVERAGEIF(Table1[product_id],Master_tbl!B1001:B2002,Table1[competitor_price]) -> 4666.1267 | N1001: =IFERROR(Table5[[#This Row],[final_sale_price]]*Table5[[#This Row],[quantity_sold ]],0) -> 10856.192 | O1001: =(Table5[[#This Row],[final_sale_price]]-Table5[[#This Row],[cost_price]])*Table5[[#This Row],[quantity_sold ]] -> 3999.6495 | P1001: =(Table5[final_sale_price]-Table5[[#This Row],[avg_comp_price]]) -> -4027.5272 | Q1001: =(Table5[[#This Row],[final_sale_price]]-Table5[[#This Row],[avg_comp_price]])/Table5[[#This Row],[avg_comp_price]] -> -0.86314141 | R1001: =Table5[[#This Row],[Profit]]/Table5[[#This Row],[Revenue]] -> 0.36842105
R1002: =Table5[[#This Row],[Profit]]/Table5[[#This Row],[Revenue]] -> #DIV/0!
R1003: =Table5[[#This Row],[Profit]]/Table5[[#This Row],[Revenue]] -> #DIV/0!

Sheet Products
A1: product_id | B1: product_name | C1: category | D1: cost_price | E1: base_price
A2: 1 | B2: Wheat Flour 1 | C2: Grocery | D2: 1146.57 | E2: 1910.95
A3: 2 | B3: Air Conditioner 2 | C3: Home Appliances | D3: 2654.868 | E3: 4424.78
A4: 3 | B4: Biography 3 | C4: Books | D4: 3100.068 | E4: 5166.78
A5: 4 | B5: Gym Gloves 4 | C5: Sports | D5: 4251.228 | E5: 7085.38
A6: 5 | B6: Moisturizer 5 | C6: Beauty | D6: 498.15 | E6: 830.25
A7: 6 | B7: Microwave 6 | C7: Home Appliances | D7: 2475.108 | E7: 4125.18
A8: 7 | B8: Handbag 7 | C8: Fashion | D8: 5018.88 | E8: 8364.8
A9: 8 | B9: Puzzle Set 8 | C9: Toys | D9: 3386.364 | E9: 5643.94
A10: 9 | B10: Air Conditioner 9 | C10: Home Appliances | D10: 1718.31 | E10: 2863.85
A11: 10 | B11: Jacket 10 | C11: Fashion | D11: 1678.374 | E11: 2797.29
A12: 11 | B12: Remote Car 11 | C12: Toys | D12: 1920.12 | E12: 3200.2
A13: 12 | B13: Running Shoes 12 | C13: Sports | D13: 969.15 | E13: 1615.25
... A151: 150 | B151: Puzzle Set 150 | C151: Toys | D151: 1373.832 | E151: 2289.72

Sheet Sales
A1: sale_id | B1: product_id | C1: sale_date | D1: quantity_sold | E1: discount_percent | F1: final_sale_price
A2: 1 | B2: 90 | C2: 45878 | D2: 12 | E2: 4 | F2: 1321.6416
A3: 2 | B3: 117 | C3: 45372 | D3: 35 | E3: 2 | F3: 2084.6364
A4: 3 | B4: 27 | C4: 45339 | D4: 14 | E4: 2 | F4: 1590.442
A5: 4 | B5: 48 | C5: 45660 | D5: 9 | E5: 3 | F5: 3577.6219
A6: 5 | B6: 121 | C6: 45115 | D6: 49 | E6: 6 | F6: 1422.3892
A7: 6 | B7: 101 | C7: 45097 | D7: 48 | E7: 5 | F7: 4484.2755
A8: 7 | B8: 117 | C8: 45411 | D8: 47 | E8: 2 | F8: 2084.6364
A9: 8 | B9: 22 | C9: 45215 | D9: 5 | E9: 10 | F9: 1471.05
A10: 9 | B10: 82 | C10: 45795 | D10: 50 | E10: 4 | F10: 1220.3712
A11: 10 | B11: 94 | C11: 45067 | D11: 16 | E11: 5 | F11: 4420.141
A12: 11 | B12: 40 | C12: 45755 | D12: 3 | E12: 7 | F12: 457.8111
A13: 12 | B13: 50 | C13: 45784 | D13: 47 | E13: 9 | F13: 1234.597
... A1001: 1000 | B1001: 134 | C1001: 45675 | D1001: 17 | E1001: 5 | F1001: 638.5995

Sheet Comp_prices
A1: comp_id | B1: product_id | C1: competitor_name | D1: competitor_price
A2: 1 | B2: 1 | C2: Snapdeal | D2: 4898.2
A3: 2 | B3: 1 | C3: Amazon | D3: 5017.28
A4: 3 | B4: 1 | C4: Reliance Digital | D4: 4473.76
A5: 4 | B5: 1 | C5: Croma | D5: 4954.65
A6: 5 | B6: 1 | C6: Flipkart | D6: 4166.86
A7: 6 | B7: 1 | C7: Paytm Mall | D7: 5199.3
A8: 7 | B8: 2 | C8: Tata Cliq | D8: 2175.47
A9: 8 | B9: 2 | C9: Myntra | D9: 1404.32
A10: 9 | B10: 2 | C10: Snapdeal | D10: 1992.05
A11: 10 | B11: 2 | C11: Reliance Digital | D11: 1835.16
A12: 11 | B12: 2 | C12: Future Group | D12: 1629.5
A13: 12 | B13: 3 | C13: Snapdeal | D13: 6458.12
... A400: 399 | B400: 89 | C400: Reliance Digital | D400: 862.73
A401: 400 | C401: Big Bazaar | D401: 768.74
A402: 401 | B402: 89 | C402: Croma | D402: 963.31
A403: 402 | B403: 90 | C403: Amazon | D403: 2329.46
A404: 403 | B404: 90 | C404: Croma | D404: 2478.37
A405: 404 | B405: 90 | C405: Future Group | D405: 1980.78
A406: 405 | B406: 90 | C406: Tata Cliq | D406: 2870.41
A407: 406 | B407: 91 | C407: Snapdeal | D407: 4554.55
A408: 407 | B408: 91 | C408: Flipkart | D408: 4882.36
A409: 408 | B409: 91 | C409: Future Group | D409: 5826.51
A410: 409 | B410: 91 | C410: Croma | D410: 5600.51
A411: 410 | B411: 91 | C411: Reliance Digital | D411: 3235.75
A412: 411 | B412: 91 | C412: Myntra | D412: 4593.78
A413: 412 | B413: 92 | C413: Croma | D413: 5699.88
... A658: 657 | B658: 150 | C658: Amazon | D658: 1814.03

Sheet Reviews
A1: review_id | B1: product_id | C1: rating
A2: 118 | B2: 1 | C2: 5
A3: 207 | B3: 1 | C3: 2
A4: 381 | B4: 1 | C4: 3
A5: 392 | B5: 1 | C5: 4
A6: 440 | B6: 1 | C6: 1
A7: 512 | B7: 1 | C7: 3
A8: 689 | B8: 1 | C8: 4
A9: 709 | B9: 1 | C9: 5
A10: 942 | B10: 1 | C10: 2
A11: 26 | B11: 2 | C11: 4
A12: 37 | B12: 2 | C12: 1
A13: 557 | B13: 2 | C13: 5
... A1001: 566 | B1001: 150 | C1001: 3
